<?xml version="1.0"?>
<robot name="ugress">
  
  <!-- ============ BASE LINK (Chassis) ============ -->
  <link name="base_link">
    <visual>
      <geometry>
        <box size="0.8 0.6 0.3"/>
      </geometry>
      <material name="blue">
        <color rgba="0.2 0.2 0.8 1"/>
      </material>
    </visual>
    <collision>
      <geometry>
        <box size="0.8 0.6 0.3"/>
      </geometry>
    </collision>
    <inertial>
      <mass value="15.0"/>
      <origin xyz="0 0 0" rpy="0 0 0"/>
      <inertia ixx="0.5" ixy="0.0" ixz="0.0" iyy="0.5" iyz="0.0" izz="0.5"/>
    </inertial>
  </link>

  <!-- ============ LEFT WHEEL ============ -->
  <link name="left_wheel">
    <visual>
      <geometry>
        <cylinder radius="0.15" length="0.05"/>
      </geometry>
      <material name="black">
        <color rgba="0.1 0.1 0.1 1"/>
      </material>
    </visual>
    <collision>
      <geometry>
        <cylinder radius="0.15" length="0.05"/>
      </geometry>
    </collision>
    <inertial>
      <mass value="1.0"/>
      <inertia ixx="0.01" ixy="0.0" ixz="0.0" iyy="0.01" iyz="0.0" izz="0.01"/>
    </inertial>
  </link>

  <joint name="left_wheel_joint" type="continuous">
    <parent link="base_link"/>
    <child link="left_wheel"/>
    <origin xyz="0 0.35 -0.1" rpy="0 1.57 0"/>
    <axis xyz="0 0 1"/>
  </joint>

  <!-- ============ RIGHT WHEEL ============ -->
  <link name="right_wheel">
    <visual>
      <geometry>
        <cylinder radius="0.15" length="0.05"/>
      </geometry>
      <material name="black">
        <color rgba="0.1 0.1 0.1 1"/>
      </material>
    </visual>
    <collision>
      <geometry>
        <cylinder radius="0.15" length="0.05"/>
      </geometry>
    </collision>
    <inertial>
      <mass value="1.0"/>
      <inertia ixx="0.01" ixy="0.0" ixz="0.0" iyy="0.01" iyz="0.0" izz="0.01"/>
    </inertial>
  </link>

  <joint name="right_wheel_joint" type="continuous">
    <parent link="base_link"/>
    <child link="right_wheel"/>
    <origin xyz="0 -0.35 -0.1" rpy="0 1.57 0"/>
    <axis xyz="0 0 1"/>
  </joint>

  <!-- ============ FRONT CASTER WHEEL ============ -->
  <link name="caster_wheel">
    <visual>
      <geometry>
        <sphere radius="0.08"/>
      </geometry>
      <material name="gray">
        <color rgba="0.5 0.5 0.5 1"/>
      </material>
    </visual>
    <collision>
      <geometry>
        <sphere radius="0.08"/>
      </geometry>
    </collision>
    <inertial>
      <mass value="0.5"/>
      <inertia ixx="0.001" ixy="0.0" ixz="0.0" iyy="0.001" iyz="0.0" izz="0.001"/>
    </inertial>
  </link>

  <joint name="caster_wheel_joint" type="fixed">
    <parent link="base_link"/>
    <child link="caster_wheel"/>
    <origin xyz="0.3 0 -0.18" rpy="0 0 0"/>
  </joint>

  <!-- ============ GAZEBO DIFFERENTIAL DRIVE PLUGIN ============ -->
  <gazebo>
    <plugin name="differential_drive_controller" filename="libgazebo_ros_diff_drive.so">
      <updateRate>20</updateRate>
      <leftJoint>left_wheel_joint</leftJoint>
      <rightJoint>right_wheel_joint</rightJoint>
      <wheelSeparation>0.7</wheelSeparation>
      <wheelDiameter>0.3</wheelDiameter>
      <torque>20</torque>
      <commandTopic>cmd_vel</commandTopic>
      <odometryTopic>odom</odometryTopic>
      <odometryFrame>odom</odometryFrame>
      <robotBaseFrame>base_link</robotBaseFrame>
      <publishWheelTF>true</publishWheelTF>
      <publishWheelJointState>true</publishWheelJointState>
      <publishOdom>true</publishOdom>
      <publishTf>true</publishTf>
      <legacyMode>false</legacyMode>
    </plugin>
  </gazebo>

  <!-- ============ GAZEBO MATERIALS ============ -->
  <gazebo reference="base_link">
    <material>Gazebo/Blue</material>
  </gazebo>
  <gazebo reference="left_wheel">
    <material>Gazebo/Black</material>
    <mu1>1.0</mu1>
    <mu2>1.0</mu2>
  </gazebo>
  <gazebo reference="right_wheel">
    <material>Gazebo/Black</material>
    <mu1>1.0</mu1>
    <mu2>1.0</mu2>
  </gazebo>
  <gazebo reference="caster_wheel">
    <material>Gazebo/Gray</material>
    <mu1>0.0</mu1>
    <mu2>0.0</mu2>
  </gazebo>

</robot>
